<?xml version="1.0" ?>
<robot xmlns:xacro="http://ros.org/wiki/xacro" name="rcv">
<!--- Surface properties must come first? -->
<gazebo reference="front_left_wheel">
  <mu1>0.9</mu1>
  <mu2>0.9</mu2>
  <minDepth>0.005</minDepth>
  <kp>1e8</kp>
</gazebo>
<gazebo reference="front_right_wheel">
  <mu1>0.9</mu1>
  <mu2>0.9</mu2>
  <minDepth>0.005</minDepth>
  <kp>1e8</kp>
</gazebo>
<gazebo reference="rear_left_wheel">
  <mu1>0.9</mu1>
  <mu2>0.9</mu2>
  <minDepth>0.005</minDepth>
  <kp>1e8</kp>
</gazebo>
<gazebo reference="rear_right_wheel">
  <mu1>0.9</mu1>
  <mu2>0.9</mu2>
  <minDepth>0.005</minDepth>
  <kp>1e8</kp>
</gazebo>


  <!-- Base link is the actual robot body, on the ground-->
  <link name="base_link">
    <inertial>
      <mass value="1"/>
      <inertia ixx="0.001" ixy="0.0" ixz="0.0" iyy="0.001" iyz="0.0" izz="0.001"/>
    </inertial>
  </link>
  <joint name="base_link_connection" type="fixed">
    <parent link="base_link"/>
    <child link="chassis"/>
    <origin xyz="1.45 0 0" rpy="0 0 1.57"/>
    <axis xyz="1 0 0"/>
  </joint>

<link name="chassis">
  <visual>
    <origin xyz="0 0 0" rpy="0 0 1.57"/>
    <geometry>
      <!-- TODO adjust the scale of the mesh -->
      <mesh filename="package://rcv_description/meshes/RCV_assembly_stl_downsample.dae" scale="0.0264 0.0264 0.0264"/>
    </geometry>
  </visual>

  <!-- TODO adjust the size of collision boxes -->
  <collision name="chassis">
    <origin xyz="0.0 0.05 0.625" rpy="0 0 0"/>
    <geometry>
      <box size="1.7526 2.1 0.95"/>
    </geometry>
  </collision>

  <collision name="front_bumper">
    <origin xyz="0.0 -2.0 0.458488" rpy="0.0 0 0"/>
    <geometry>
      <box size="1.337282 0.48 0.566691"/>
    </geometry>
  </collision>

  <collision name="hood">
    <origin xyz="0.0 -1.900842 0.676305" rpy="0.341247 0 0"/>
    <geometry>
      <box size="1.597968 0.493107 0.265468"/>
    </geometry>
  </collision>


  <collision name="top_front">
    <origin xyz="0.0 0.161236 1.386042" rpy="0.135030 0 0"/>
    <geometry>
      <box size="1.279154 0.625988 0.171868"/>
    </geometry>
  </collision>

  <collision name="top_rear">
    <origin xyz="0.0 0.817696 1.360069" rpy="-0.068997 0 0"/>
    <geometry>
      <box size="1.285130 0.771189 0.226557"/>
    </geometry>
  </collision>

  <collision name="back_bumper">
    <origin xyz="0.0 2.054454 0.577870" rpy="0.0 0 0"/>
    <geometry>
      <box size="1.781650 0.512093 0.581427"/>
    </geometry>
  </collision>

<!-- TODO adjust the mass -->
  <inertial>
    <mass value="400.0"/>
    <origin xyz="0 0 0.48" rpy="0 0 1.5708"/>
    <inertia ixx="2581.13354740" ixy="0.0" ixz="0.0" iyy="591.30846112" iyz="0.0" izz="2681.95008628"/>
  </inertial>
</link>

<link name="fl_axle">
  <inertial>
    <mass value="1"/>
    <origin xyz="0 0 0"/>
    <inertia ixx="0.004" ixy="0.0" ixz="0.0" iyy="0.004" iyz="0.0" izz="0.004"/>
  </inertial>
</link>

<link name="fr_axle">
  <inertial>
    <mass value="1"/>
    <origin xyz="0 0 0"/>
    <inertia ixx="0.004" ixy="0.0" ixz="0.0" iyy="0.004" iyz="0.0" izz="0.004"/>
  </inertial>
</link>
  
<link name="rl_axle">
  <inertial>
    <mass value="1"/>
    <origin xyz="0 0 0"/>
    <inertia ixx="0.004" ixy="0.0" ixz="0.0" iyy="0.004" iyz="0.0" izz="0.004"/>
  </inertial>
</link>

<link name="rr_axle">
  <inertial>
    <mass value="1"/>
    <origin xyz="0 0 0"/>
    <inertia ixx="0.004" ixy="0.0" ixz="0.0" iyy="0.004" iyz="0.0" izz="0.004"/>
  </inertial>
</link>

<link name="front_left_wheel">
  <inertial>
    <mass value="25"/>
    <origin xyz="0 0 0"/>
    <inertia ixx="0.58631238" ixy="0.0" ixz="0.0" iyy="0.33552910" iyz="0.0" izz="0.33552910"/>
  </inertial>
  <collision name="front_left_wheel_collision">
    <geometry>
      <sphere radius="0.31265"/>
    </geometry>

<!--you can't set friction in URDF -->
    <surface>
      <friction>
        <torsional>
<coefficient>1.0</coefficient>
<surface_radius>0.5</surface_radius>
<use_patch_radius>false</use_patch_radius>
        </torsional>
      </friction>
    </surface>


  </collision>
  <visual>
    <origin xyz="0 0 0" rpy="0 0 0"/>
    <geometry>
      <mesh filename="package://prius_description/meshes/wheel.obj" scale="0.01 0.01 0.01"/>
    </geometry>
  </visual>
</link>

<link name="front_right_wheel">
  <inertial>
    <mass value="25"/>
    <origin xyz="0 0 0"/>
    <inertia ixx="0.58631238" ixy="0.0" ixz="0.0" iyy="0.33552910" iyz="0.0" izz="0.33552910"/>
  </inertial>
  <collision name="front_right_wheel_collision">
    <geometry>
      <sphere radius="0.31265"/>
    </geometry>
  </collision>
  <visual>
    <origin xyz="0 0 0" rpy="0 0 0"/>
    <geometry>
      <mesh filename="package://prius_description/meshes/wheel.obj" scale="0.01 0.01 0.01"/>
    </geometry>
  </visual>
</link>

<link name="rear_left_wheel">
  <inertial>
    <mass value="25"/>
    <origin xyz="0 0 0"/>
    <inertia ixx="0.58631238" ixy="0.0" ixz="0.0" iyy="0.33552910" iyz="0.0" izz="0.33552910"/>
  </inertial>
  <collision name="rear_left_wheel_collision">
    <geometry>
      <sphere radius="0.31265"/>
    </geometry>
  </collision>
  <visual>
    <origin xyz="0 0 0" rpy="0 0 0"/>
    <geometry>
      <mesh filename="package://prius_description/meshes/wheel.obj" scale="0.01 0.01 0.01"/>
    </geometry>
  </visual>
</link>

<link name="rear_right_wheel">
  <inertial>
    <mass value="25"/>
    <origin xyz="0 0 0"/>
    <inertia ixx="0.58631238" ixy="0.0" ixz="0.0" iyy="0.33552910" iyz="0.0" izz="0.33552910"/>
  </inertial>
  <collision name="rear_right_wheel_collision">
    <geometry>
      <sphere radius="0.31265"/>
    </geometry>
  </collision>
  <visual>
    <origin xyz="0 0 0" rpy="0 0 0"/>
    <geometry>
      <mesh filename="package://prius_description/meshes/wheel.obj" scale="0.01 0.01 0.01"/>
    </geometry>
  </visual>
</link>

<link name="steering_wheel">
  <inertial>
    <mass value="1.0"/>
    <inertia ixx="0.14583300" ixy="0.0" ixz="0.0" iyy="0.14583300" iyz="0.0" izz="0.125"/>
  </inertial>
  <visual>
    <origin xyz="0 0 0" rpy="1.302101 0 0"/>
    <geometry>
      <mesh filename="package://prius_description/meshes/steering_wheel.obj" scale="0.01 0.01 0.01"/>
    </geometry>
  </visual>
</link>

<!-- TODO adjust positions of these joints -->
<joint name="steering_joint" type="continuous">
  <origin xyz="0.357734 -0.627868 0.988243" rpy="-1.302101 0 0"/>
  <parent link="chassis"/>
  <child link="steering_wheel"/>
  <axis xyz="0 0 1"/>
  <limit lower="-7.85" upper="7.85" effort="10000000" velocity="1000000"/>
</joint>

<joint name="front_left_steer_joint" type="continuous">
  <parent link="chassis"/>
  <child link="fl_axle"/>
  <origin xyz="0.75 -1.0 0.3" rpy="0 0 0"/>
  <axis xyz="0 0 1"/>
  <limit lower="-0.8727" upper="0.8727" effort="10000000" velocity="1000000"/>
</joint>

<joint name="front_right_steer_joint" type="continuous">
  <parent link="chassis"/>
  <child link="fr_axle"/>
  <origin xyz="-0.75 -1.0 0.3" rpy="0 0 0"/>
  <axis xyz="0 0 1"/>
  <limit lower="-0.8727" upper="0.8727" effort="10000000" velocity="1000000"/>
</joint>
  
  <!-- TODO add joints for steering rear wheels -->
<joint name="rear_left_steer_joint" type="continuous">
  <parent link="chassis"/>
  <child link="rl_axle"/>
  <origin xyz="0.75 1.0 0.3" rpy="0 0 0"/>
  <axis xyz="0 0 1"/>
  <limit lower="-0.8727" upper="0.8727" effort="10000000" velocity="1000000"/>
</joint>

<joint name="rear_right_steer_joint" type="continuous">
  <parent link="chassis"/>
  <child link="rr_axle"/>
  <origin xyz="-0.75 1.0 0.3" rpy="0 0 0"/>
  <axis xyz="0 0 1"/>
  <limit lower="-0.8727" upper="0.8727" effort="10000000" velocity="1000000"/>
</joint>
  
  
<joint name="front_left_wheel_joint" type="continuous">
  <parent link="fl_axle"/>
  <child link="front_left_wheel"/>
  <origin xyz="0 0 0" rpy="0 0 0"/>
  <axis xyz="1 0 0"/>
</joint>
<joint name="front_right_wheel_joint" type="continuous">
  <parent link="fr_axle"/>
  <child link="front_right_wheel"/>
  <origin xyz="0 0 0" rpy="0 0 0"/>
  <axis xyz="1 0 0"/>
</joint>
<joint name="rear_left_wheel_joint" type="continuous">
  <parent link="rl_axle"/>
  <child link="rear_left_wheel"/>
  <origin xyz="0 0 0" rpy="0 0 0"/>
  <axis xyz="1 0 0"/>
</joint>
<joint name="rear_right_wheel_joint" type="continuous">
  <parent link="rr_axle"/>
  <child link="rear_right_wheel"/>
  <origin xyz="0 0 0" rpy="0 0 0"/>
  <axis xyz="1 0 0"/>
</joint>


  <!-- Sensors -->
  <!-- TODO fix!
  <link name="sensor_board_link"/>
  <link name="velodyne_left"/>
  <link name="velodyne_right"/>
  <link name="trimble"/>
  <link name="left_optical"/>
  <link name="right_optical"/>
  <link name="imu"/>

  <joint name="trimble_joint" type="fixed" >
    <origin rpy="0 0 0"
            xyz="0.09 0 -1.2" />
    <parent link="trimble"/>
    <child link="base_link"/>
  </joint>

  <joint name="base_sensor_board_joint" type="fixed" >
    <origin rpy="0 0 0"
            xyz="-0.45 0 1.2" />
    <parent link="base_link"/>
    <child link="sensor_board_link"/>
  </joint>

  <joint name="velodyne_right_joint" type="fixed" >
    <origin rpy="0 0 -1.63"
            xyz="0 -0.7 0" />
    <parent link="sensor_board_link"/>
    <child link="velodyne_right"/>
  </joint>

  <joint name="velodyne_left_joint" type="fixed" >
    <origin rpy="0 0 1.57"
            xyz="0 0.675 0" />
    <parent link="sensor_board_link"/>
    <child link="velodyne_left"/>
  </joint>

  <joint name="imu_joint" type="fixed" >
    <origin rpy="0 0 0"
            xyz="0 0 0.15" />
    <parent link="base_link"/>
    <child link="imu"/>
  </joint>

  <joint name="camera_left_joint" type="fixed" >
    <origin rpy="-1.5707963267948966 0 -1.5707963267948966"
            xyz="0 0.5 0" />
    <parent link="sensor_board_link"/>
    <child link="left_optical"/>
  </joint>

  <joint name="camera_right_joint" type="fixed" >
    <origin rpy="0 0 0"
            xyz="0 -0.5 0" />
    <parent link="sensor_board_link"/>
    <child link="right_optical"/>
  </joint>
  -->
<gazebo reference="base_link_connection">
  <disableFixedJointLumping>true</disableFixedJointLumping>
</gazebo>

<gazebo>
  <plugin name="rcv_four_wheel_steer" filename="libRCVPlugin.so">
    <chassis>chassis</chassis>
    <front_left_wheel>front_left_wheel_joint</front_left_wheel>
    <front_right_wheel>front_right_wheel_joint</front_right_wheel>
    <front_left_wheel_steering>front_left_steer_joint</front_left_wheel_steering>
    <front_right_wheel_steering>front_right_steer_joint</front_right_wheel_steering>
    <back_left_wheel_steering>rear_left_steer_joint</back_left_wheel_steering>
    <back_right_wheel_steering>rear_right_steer_joint</back_right_wheel_steering>
    <back_left_wheel>rear_left_wheel_joint</back_left_wheel>
    <back_right_wheel>rear_right_wheel_joint</back_right_wheel>
    <steering_wheel>steering_joint</steering_wheel>
    <chassis_aero_force_gain>0.63045</chassis_aero_force_gain>
    <front_torque>859.4004393000001</front_torque>
    <back_torque>859.4004393000001</back_torque>
    <front_brake_torque>687.5203514400001</front_brake_torque>
    <back_brake_torque>687.5203514400001</back_brake_torque>
    <max_speed>37.998337013956565</max_speed>
    <max_steer>0.6458</max_steer>
    <flwheel_steering_p_gain>1e3</flwheel_steering_p_gain>
    <frwheel_steering_p_gain>1e3</frwheel_steering_p_gain>
    <flwheel_steering_i_gain>0</flwheel_steering_i_gain>
    <frwheel_steering_i_gain>0</frwheel_steering_i_gain>
    <flwheel_steering_d_gain>3e2</flwheel_steering_d_gain>
    <frwheel_steering_d_gain>3e2</frwheel_steering_d_gain>
    <blwheel_steering_p_gain>1e3</blwheel_steering_p_gain>
    <brwheel_steering_p_gain>1e3</brwheel_steering_p_gain>
    <blwheel_steering_i_gain>0</blwheel_steering_i_gain>
    <brwheel_steering_i_gain>0</brwheel_steering_i_gain>
    <blwheel_steering_d_gain>3e2</blwheel_steering_d_gain>
    <brwheel_steering_d_gain>3e2</brwheel_steering_d_gain>
  </plugin>
</gazebo>

<gazebo>
  <plugin name="joint_state_publisher" filename="libgazebo_ros_joint_state_publisher.so">
    <!-- <robotNamespace>/prius</robotNamespace> -->
    <jointName>rear_right_wheel_joint, rear_left_wheel_joint, front_right_wheel_joint, front_left_wheel_joint, front_right_steer_joint, front_left_steer_joint, rear_right_steer_joint, rear_left_steer_joint, steering_joint</jointName>
    <updateRate>100.0</updateRate>
    <alwaysOn>true</alwaysOn>
  </plugin>
</gazebo>

<gazebo>
  <plugin name="p3d" filename="libgazebo_ros_p3d.so">
    <!-- <robotNamespace>/prius</robotNamespace> -->
    <bodyName>base_link</bodyName>
    <topicName>base_pose_ground_truth</topicName>
    <frameName>map</frameName>
    <updateRate>100.0</updateRate>
  </plugin>
</gazebo>

<!-- TODO add sensors in gazebo -->

</robot>
